Workbook

Sheet README
A1: Usage-Based AI FP&A Toolkit: Spreadsheet Model
A2: Version 1.0.0 | Author: Ankit Chopra | License: MIT (free to use, share and adapt with attribution)
A4: What this is
A5: Purpose | B5: A simple, transparent Base Model for planning usage-based cloud and AI products. It links usage to revenue, LLM cost, cloud cost and gross margin, and expresses ROI as a risk-adjusted range instead of a single number.
A6: Where it comes from | B6: It turns the planning engine in Chopra, A. (2026), 'Financial Planning for Agentic & AI Systems: Managing Volatility in the Age of Autonomy', California Management Review Insights, 17 Feb 2026 (https://cmr.berkeley.edu/2026/02/financial-planning-for-agentic-ai-systems-managing-volatility-in-the-age-of-autonomy/) into a working spreadsheet: usage drives cost, pricing converts usage to revenue, and ROI is a corridor between a standard ceiling and a risk-adjusted floor.
A7: Who it is for | B7: FP&A, finance and product leaders planning AI features or AI-enabled products with usage-based, hybrid or prepaid pricing.
A8: Important | B8: All example numbers are synthetic and illustrative. They do not represent any company. Replace them with your own data before drawing conclusions. This is decision support: accountability for decisions stays with the people using it. It is not financial advice.
A10: Quick start (3 steps)
A11: 1. Edit Inputs | B11: Go to the Inputs sheet. Change only blue-on-yellow cells. Start with the scenario levers, then usage, pricing, LLM cost, the three cloud rates, and the upfront investment. Check that the Input checks block shows OK.
A12: 2. Read Summary | B12: The Summary sheet shows the ROI corridor (floor and ceiling), payback month, the adoption dip, annual results, cost mix, and whether unit costs are falling while total spend rises. Two charts show the dip and gross margin by month.
A13: 3. Refine | B13: Use the three Model tabs (Low, Base, High) to trace any number. Each is a monthly build over 36 months with identical formulas. Add actuals on Inputs to compare realized ROI with plan.
A15: Sheet guide
A16: README | B16: This page.
A17: Methodology_Data | B17: Every formula in plain English, where to get each input, how to calibrate the cloud rates, the ROI method, limitations, and planned next versions.
A18: Inputs | B18: All assumptions in one place. Scenario levers have Low, Base and High columns. Everything else is a single value.
A19: Model_Low / Model_Base / Model_High | B19: Monthly model for each scenario: usage, revenue, cost of revenue, gross margin, cumulative position, unit economics.
A20: Summary | B20: Results and charts. Fully formula-driven.
A22: Colour legend
A23: Blue text, yellow fill | B23: Input: safe to edit.
A24: Black text | B24: Formula: do not overwrite.
A25: Green text | B25: Link to another sheet.
A27: Companion files
A28: Python script | B28: agentic_ai_fpa_model.py reproduces the same model from a JSON file and adds a Monte Carlo run. Results match this workbook.
A29: LLM package | B29: SKILL.md and prompt.md let you load the method into a custom GPT or similar assistant to build, edit and sense-check your own models.
A30: How to cite | B30: Chopra, A. (2026). Usage-Based AI FP&A Toolkit (v1.0.0) [Software]. Companion to: Financial Planning for Agentic & AI Systems, California Management Review Insights. Add the DOI or repository link here once published.

Sheet Methodology_Data
A1: Methodology and data guide
A2: How the model works, what data it needs, and where it stops being reliable.
A4: 1. Model flow
A5: Flow | B5: Customers x interactions per customer = total interactions. Interactions x tokens per interaction = total tokens. Tokens x price (with a prepaid discount on part of the volume) = revenue. Tokens x provider cost x (1 - efficiency gain) = LLM cost. Interactions x fully loaded cloud rate x (1 - discount) = cloud cost. Revenue - all costs = gross margin. | C5: Matches the Base Model in the CMR article: usage forecast feeds both revenue and cost forecasts.
A6: Time and scenarios | B6: Monthly, 36 months, three scenarios (Low = conservative, Base, High = optimistic). Scenarios differ only in the five levers at the top of Inputs. Everything else is common. | C6: Scenario tabs share identical formulas so results are comparable.
A8: 2. Formulas in plain English | B8: Formula | C8: Notes
A9: Active customers | B9: Starting customers x (1 + monthly growth) ^ (month - 1) | C9: Compound growth.
A10: Interactions per customer | B10: Month 1 interactions x (1 + monthly intensity growth) ^ (month - 1) | C10: Captures rising usage per customer.
A11: Total interactions | B11: Customers x interactions per customer | C11: The single driver for usage, revenue and cloud cost.
A12: Total tokens (000s) | B12: Interactions x tokens per interaction / 1,000 | C12: Tokens held constant per interaction in v1.
A13: On-demand revenue | B13: Tokens (000s) x (1 - prepaid share) x price per 1,000 tokens | C13: Pay-as-you-go volume.
A14: Prepaid revenue | B14: Tokens (000s) x prepaid share x price x (1 - prepaid discount) | C14: Prepaid blocks sold at a discounted rate.
A15: Subscription revenue | B15: Customers x base subscription fee | C15: Zero by default. Use for hybrid pricing.
A16: LLM cost per 1,000 tokens | B16: Provider cost x (1 - annual decline) ^ ((month - 1) / 12) | C16: Annual decline compounded monthly.
A17: LLM cost | B17: Tokens (000s) x LLM cost per 1,000 tokens x (1 - efficiency gain) | C17: Efficiency gain applies to LLM cost only.
... A41: Avoid double counting | B41: Enter rates at list-equivalent cost if you apply a discount on Inputs. If your rates already include discounts, set the discount to 0%. | C41: One or the other, not both.
A42: Why separate components | B42: The mix shows what drives cloud cost and which component grows fastest as usage scales. It is an output on the Summary sheet.
A44: 5. ROI method | B44: Detail
A45: Three stages | B45: Pre-investment: ROI is a corridor with a standard ceiling and a risk-adjusted floor. Implementation: the cumulative net position shows the adoption dip and payback. Production: replace plan with actuals and compare realized ROI with plan at the same month. | C45: Follows the three-stage ROI governance framework (evaluation, adoption dip, realized returns).
A46: Assumptions | B46: Net gain = cumulative gross margin over 36 months. Investment = upfront investment input. Risk haircuts combine by multiplication. | C46: These are modelling choices, not rules. Change them if your finance policy differs.
A48: 6. Limitations
A49: Simplifications in v1 | B49: One blended cloud discount (no commitment minimum or take-or-pay shortfall). Tokens per interaction are constant. Efficiency gain is constant and applied to LLM cost only. No seasonality. Three discrete scenarios rather than probabilities (the Python script adds a Monte Carlo run). Gross margin is the benefit; operating expenses are not modelled. Single currency, no taxes or financing. | C49: Good for planning conversations and sensitivities. Not a substitute for an audited forecast.
A50: Data quality | B50: Results are only as good as the inputs. Re-calibrate rates and discounts regularly because AI unit costs change quickly.
A52: 7. Next versions
A53: Ideas, not in v1 | B53: Cohort and price-elasticity models, outcome-linked pricing, commitment minimums, multi-cloud and per-service views, and an ML ensemble layer that learns from actuals. | C53: Contributions and suggestions welcome.
A55: 8. Licence, version, citation
A56: Licence | B56: MIT. Free to use, copy, modify and share with attribution.
A57: Version | B57: 1.0.0
A58: Cite as | B58: Chopra, A. (2026). Usage-Based AI FP&A Toolkit (v1.0.0). Companion to 'Financial Planning for Agentic & AI Systems: Managing Volatility in the Age of Autonomy', California Management Review Insights. | C58: Add DOI or repository link once published.

Sheet Inputs
A1: Inputs: every assumption lives on this sheet
A2: Blue text on yellow = cell you can edit. Black = formula. All example values are synthetic and illustrative; replace them with your own.
A4: Scenario levers | B4: Unit | C4: Low | D4: Base | E4: High | F4: Notes
A5: Monthly customer growth | B5: % per month | C5: 0.02 | D5: 0.04 | E5: 0.06 | F5: Net growth in active customers. Low = conservative case, High = optimistic case.
A6: Monthly growth in interactions per customer | B6: % per month | C6: 0.005 | D6: 0.01 | E6: 0.015 | F6: Usage intensity. Captures rising consumption per customer (the Jevons pattern).
A7: Annual LLM token cost decline | B7: % per year | C7: 0.1 | D7: 0.25 | E7: 0.4 | F7: Decline in provider cost per 1,000 tokens, compounded monthly.
A8: Annual cloud unit cost decline | B8: % per year | C8: 0 | D8: 0.05 | E8: 0.1 | F8: Decline in fully loaded cloud cost per 1,000 interactions, compounded monthly.
A9: Efficiency gain on LLM cost | B9: % of LLM cost | C9: 0.05 | D9: 0.1 | E9: 0.2 | F9: Savings from caching, distillation, retrieval design, batch vs real-time. Applied to LLM cost only.
A11: Common inputs (all scenarios) | B11: Unit | C11: Value | F11: Notes / where to get it
A12: Usage
A13: Starting active customers (month 1) | B13: count | C13: 200 | F13: Product analytics or billing system.
A14: Interactions per customer per month (month 1) | B14: count | C14: 2000 | F14: An interaction = one user request handled by the AI system. Product analytics.
A15: Tokens per interaction (input + output) | B15: tokens | C15: 4000 | F15: LLM provider usage dashboard: total tokens divided by interactions.
A16: Pricing and revenue
A17: Customer price per 1,000 tokens (on-demand) | B17: $ | C17: 0.02 | F17: Your price list or effective on-demand rate.
A18: Prepaid share of token volume | B18: % | C18: 0.4 | F18: Share of volume sold in prepaid blocks or commitments.
A19: Prepaid discount vs on-demand price | B19: % | C19: 0.2 | F19: Average discount given on prepaid volume.
A20: Base subscription fee per customer per month | B20: $ | C20: 0 | F20: Optional. Enter a fee to model hybrid pricing; leave at 0 for pure usage-based pricing.
A21: LLM cost
A22: Provider cost per 1,000 tokens (blended input and output) | B22: $ | C22: 0.006 | F22: Weight input and output prices by your actual token mix.
A23: Cloud cost (fully loaded, per 1,000 interactions, before discount)
A24: Compute | B24: $ per 1,000 interactions | C24: 12 | F24: Compute spend divided by (interactions / 1,000). See Methodology_Data.
A25: Storage | B25: $ per 1,000 interactions | C25: 3 | F25: Storage spend divided by (interactions / 1,000).
A26: Network (egress, ingress, transfer) | B26: $ per 1,000 interactions | C26: 5 | F26: Network spend divided by (interactions / 1,000).
A27: Cloud discount (applied to all three components) | B27: % | C27: 0.1 | F27: Blended enterprise or committed-use discount. Do not enter rates that are already net of discount AND a discount here.
A28: Other cost of revenue
A29: Other cost of revenue (support, monitoring, tooling) | B29: % of revenue | C29: 0.05 | F29: Finance estimate.
A30: Investment and risk (for the ROI corridor)
A31: Upfront investment | B31: $ | C31: 750000 | F31: Build, integration and launch cost for the initiative.
A32: Technical risk haircut | B32: % | C32: 0.1 | F32: Uncertainty in model or system performance.
A33: Data readiness haircut | B33: % | C33: 0.1 | F33: Uncertainty in data quality and availability.
A34: Adoption haircut | B34: % | C34: 0.15 | F34: Uncertainty in user and customer adoption.
A35: Combined risk factor | B35: factor | C35: =(1-C32)*(1-C33)*(1-C34) -> 0.6885 | F35: Calculated: (1 - technical) x (1 - data) x (1 - adoption). Applied to the benefit to get the ROI floor.
A36: Production stage: actuals (optional)
A37: Months of actuals | B37: months | C37: 12 | F37: Number of months since launch for which you have actual results (1 to 36).
A38: Actual investment to date | B38: $ | C38: 750000 | F38: Illustrative example. Replace with actuals.
A39: Actual cumulative gross margin to date | B39: $ | C39: 190000 | F39: Illustrative example. Replace with actuals.
A41: Input checks | C41: Status | F41: What it tests
A42: Prepaid share between 0% and 100% | C42: =IF(AND(C18>=0,C18<=1),"OK","CHECK") -> OK | F42: Share must be a fraction between 0 and 1.
A43: Discounts below 100% | C43: =IF(AND(C19<1,C27<1),"OK","CHECK") -> OK | F43: A 100% discount would zero out revenue or cost.
...

Sheet Model_Low
A1: Monthly model: Low scenario
A2: Scenario levers (linked from Inputs) | B2: Value
A3: Monthly customer growth | B3: =Inputs!C5 -> 0.02
A4: Monthly growth in interactions per customer | B4: =Inputs!C6 -> 0.005
A5: Annual LLM token cost decline | B5: =Inputs!C7 -> 0.1
A6: Annual cloud unit cost decline | B6: =Inputs!C8 -> 0
A7: Efficiency gain on LLM cost | B7: =Inputs!C9 -> 0.05
A8: Line item | B8: Unit | C8: 1 | D8: 2 | E8: 3 | F8: 4 | G8: 5 | H8: 6 | I8: 7 | J8: 8 | K8: 9 | L8: 10 | M8: 11 | N8: 12 | O8: 13 | P8: 14 | Q8: 15 | R8: 16 | S8: 17 | T8: 18 | U8: 19 | V8: 20 | W8: 21 | X8: 22 | Y8: 23 | Z8: 24 | AA8: 25 | AB8: 26 | AC8: 27 | AD8: 28 | AE8: 29 | AF8: 30 | AG8: 31 | AH8: 32 | AI8: 33 | AJ8: 34 | AK8: 35 | AL8: 36
A9: Year | C9: =ROUNDUP(C8/12,0) -> 1 | D9: =ROUNDUP(D8/12,0) -> 1 | E9: =ROUNDUP(E8/12,0) -> 1 | F9: =ROUNDUP(F8/12,0) -> 1 | G9: =ROUNDUP(G8/12,0) -> 1 | H9: =ROUNDUP(H8/12,0) -> 1 | I9: =ROUNDUP(I8/12,0) -> 1 | J9: =ROUNDUP(J8/12,0) -> 1 | ... AL9: =ROUNDUP(AL8/12,0) -> 3
A10: Usage
A11: Active customers | B11: count | C11: =Inputs!$C$13*(1+$B$3)^(C$8-1) -> 200 | D11: =Inputs!$C$13*(1+$B$3)^(D$8-1) -> 204 | E11: =Inputs!$C$13*(1+$B$3)^(E$8-1) -> 208.08 | F11: =Inputs!$C$13*(1+$B$3)^(F$8-1) -> 212.2416 | G11: =Inputs!$C$13*(1+$B$3)^(G$8-1) -> 216.48643 | H11: =Inputs!$C$13*(1+$B$3)^(H$8-1) -> 220.81616 | I11: =Inputs!$C$13*(1+$B$3)^(I$8-1) -> 225.23248 | J11: =Inputs!$C$13*(1+$B$3)^(J$8-1) -> 229.73713 | ... AL11: =Inputs!$C$13*(1+$B$3)^(AL$8-1) -> 399.97791
A12: Interactions per customer | B12: count | C12: =Inputs!$C$14*(1+$B$4)^(C$8-1) -> 2000 | D12: =Inputs!$C$14*(1+$B$4)^(D$8-1) -> 2010 | E12: =Inputs!$C$14*(1+$B$4)^(E$8-1) -> 2020.05 | F12: =Inputs!$C$14*(1+$B$4)^(F$8-1) -> 2030.1502 | G12: =Inputs!$C$14*(1+$B$4)^(G$8-1) -> 2040.301 | H12: =Inputs!$C$14*(1+$B$4)^(H$8-1) -> 2050.5025 | I12: =Inputs!$C$14*(1+$B$4)^(I$8-1) -> 2060.755 | J12: =Inputs!$C$14*(1+$B$4)^(J$8-1) -> 2071.0588 | ... AL12: =Inputs!$C$14*(1+$B$4)^(AL$8-1) -> 2381.4538
A13: Total interactions | B13: count | C13: =C11*C12 -> 400000 | D13: =D11*D12 -> 410040 | E13: =E11*E12 -> 420332 | F13: =F11*F12 -> 430882.34 | G13: =G11*G12 -> 441697.48 | H13: =H11*H12 -> 452784.09 | I13: =I11*I12 -> 464148.97 | J13: =J11*J12 -> 475799.11 | ... AL13: =AL11*AL12 -> 952528.91
A14: Tokens per interaction | B14: tokens | C14: =Inputs!$C$15 -> 4000 | D14: =Inputs!$C$15 -> 4000 | E14: =Inputs!$C$15 -> 4000 | F14: =Inputs!$C$15 -> 4000 | G14: =Inputs!$C$15 -> 4000 | H14: =Inputs!$C$15 -> 4000 | I14: =Inputs!$C$15 -> 4000 | J14: =Inputs!$C$15 -> 4000 | ... AL14: =Inputs!$C$15 -> 4000
A15: Total tokens (000s) | B15: 000s | C15: =C13*C14/1000 -> 1600000 | D15: =D13*D14/1000 -> 1640160 | E15: =E13*E14/1000 -> 1681328 | F15: =F13*F14/1000 -> 1723529.3 | G15: =G13*G14/1000 -> 1766789.9 | H15: =H13*H14/1000 -> 1811136.4 | I15: =I13*I14/1000 -> 1856595.9 | J15: =J13*J14/1000 -> 1903196.4 | ... AL15: =AL13*AL14/1000 -> 3810115.6
A16: Revenue
A17: On-demand tokens (000s) | B17: 000s | C17: =C15*(1-Inputs!$C$18) -> 960000 | D17: =D15*(1-Inputs!$C$18) -> 984096 | E17: =E15*(1-Inputs!$C$18) -> 1008796.8 | F17: =F15*(1-Inputs!$C$18) -> 1034117.6 | G17: =G15*(1-Inputs!$C$18) -> 1060074 | H17: =H15*(1-Inputs!$C$18) -> 1086681.8 | I17: =I15*(1-Inputs!$C$18) -> 1113957.5 | J17: =J15*(1-Inputs!$C$18) -> 1141917.9 | ... AL17: =AL15*(1-Inputs!$C$18) -> 2286069.4
A18: Prepaid tokens (000s) | B18: 000s | C18: =C15*Inputs!$C$18 -> 640000 | D18: =D15*Inputs!$C$18 -> 656064 | E18: =E15*Inputs!$C$18 -> 672531.21 | F18: =F15*Inputs!$C$18 -> 689411.74 | G18: =G15*Inputs!$C$18 -> 706715.97 | H18: =H15*Inputs!$C$18 -> 724454.55 | I18: =I15*Inputs!$C$18 -> 742638.35 | J18: =J15*Inputs!$C$18 -> 761278.58 | ... AL18: =AL15*Inputs!$C$18 -> 1524046.3
A19: On-demand revenue | B19: $ | C19: =C17*Inputs!$C$17 -> 19200 | D19: =D17*Inputs!$C$17 -> 19681.92 | E19: =E17*Inputs!$C$17 -> 20175.936 | F19: =F17*Inputs!$C$17 -> 20682.352 | G19: =G17*Inputs!$C$17 -> 21201.479 | H19: =H17*Inputs!$C$17 -> 21733.636 | I19: =I17*Inputs!$C$17 -> 22279.151 | J19: =J17*Inputs!$C$17 -> 22838.357 | ... AL19: =AL17*Inputs!$C$17 -> 45721.388
A20: Prepaid revenue (discounted rate) | B20: $ | C20: =C18*Inputs!$C$17*(1-Inputs!$C$19) -> 10240 | D20: =D18*Inputs!$C$17*(1-Inputs!$C$19) -> 10497.024 | E20: =E18*Inputs!$C$17*(1-Inputs!$C$19) -> 10760.499 | F20: =F18*Inputs!$C$17*(1-Inputs!$C$19) -> 11030.588 | G20: =G18*Inputs!$C$17*(1-Inputs!$C$19) -> 11307.456 | H20: =H18*Inputs!$C$17*(1-Inputs!$C$19) -> 11591.273 | I20: =I18*Inputs!$C$17*(1-Inputs!$C$19) -> 11882.214 | J20: =J18*Inputs!$C$17*(1-Inputs!$C$19) -> 12180.457 | ... AL20: =AL18*Inputs!$C$17*(1-Inputs!$C$19) -> 24384.74
A21: Subscription revenue | B21: $ | C21: =C11*Inputs!$C$20 -> 0 | D21: =D11*Inputs!$C$20 -> 0 | E21: =E11*Inputs!$C$20 -> 0 | F21: =F11*Inputs!$C$20 -> 0 | G21: =G11*Inputs!$C$20 -> 0 | H21: =H11*Inputs!$C$20 -> 0 | I21: =I11*Inputs!$C$20 -> 0 | J21: =J11*Inputs!$C$20 -> 0 | ... AL21: =AL11*Inputs!$C$20 -> 0
A22: Total revenue | B22: $ | C22: =SUM(C19:C21) -> 29440 | D22: =SUM(D19:D21) -> 30178.944 | E22: =SUM(E19:E21) -> 30936.435 | F22: =SUM(F19:F21) -> 31712.94 | G22: =SUM(G19:G21) -> 32508.935 | H22: =SUM(H19:H21) -> 33324.909 | I22: =SUM(I19:I21) -> 34161.364 | J22: =SUM(J19:J21) -> 35018.815 | ... AL22: =SUM(AL19:AL21) -> 70106.128
A23: Cost of revenue
A24: LLM cost per 1,000 tokens (after decline) | B24: $ | C24: =Inputs!$C$22*(1-$B$5)^((C$8-1)/12) -> 0.006 | D24: =Inputs!$C$22*(1-$B$5)^((D$8-1)/12) -> 0.0059475503 | E24: =Inputs!$C$22*(1-$B$5)^((E$8-1)/12) -> 0.0058955592 | F24: =Inputs!$C$22*(1-$B$5)^((F$8-1)/12) -> 0.0058440225 | G24: =Inputs!$C$22*(1-$B$5)^((G$8-1)/12) -> 0.0057929363 | H24: =Inputs!$C$22*(1-$B$5)^((H$8-1)/12) -> 0.0057422967 | I24: =Inputs!$C$22*(1-$B$5)^((I$8-1)/12) -> 0.0056920998 | J24: =Inputs!$C$22*(1-$B$5)^((J$8-1)/12) -> 0.0056423417 | ... AL24: =Inputs!$C$22*(1-$B$5)^((AL$8-1)/12) -> 0.004412573
A25: LLM cost (after efficiency gain) | B25: $ | C25: =C15*C24*(1-$B$7) -> 9120 | D25: =D15*D24*(1-$B$7) -> 9267.1874 | E25: =E15*E24*(1-$B$7) -> 9416.7504 | F25: =F15*F24*(1-$B$7) -> 9568.727 | G25: =G15*G24*(1-$B$7) -> 9723.1565 | H25: =H15*H24*(1-$B$7) -> 9880.0783 | I25: =I15*I24*(1-$B$7) -> 10039.533 | J25: =J15*J24*(1-$B$7) -> 10201.56 | ... AL25: =AL15*AL24*(1-$B$7) -> 15971.793
A26: Cloud cost factor (price decline x (1 - discount)) | B26: factor | C26: =(1-$B$6)^((C$8-1)/12)*(1-Inputs!$C$27) -> 0.9 | D26: =(1-$B$6)^((D$8-1)/12)*(1-Inputs!$C$27) -> 0.9 | E26: =(1-$B$6)^((E$8-1)/12)*(1-Inputs!$C$27) -> 0.9 | F26: =(1-$B$6)^((F$8-1)/12)*(1-Inputs!$C$27) -> 0.9 | G26: =(1-$B$6)^((G$8-1)/12)*(1-Inputs!$C$27) -> 0.9 | H26: =(1-$B$6)^((H$8-1)/12)*(1-Inputs!$C$27) -> 0.9 | I26: =(1-$B$6)^((I$8-1)/12)*(1-Inputs!$C$27) -> 0.9 | J26: =(1-$B$6)^((J$8-1)/12)*(1-Inputs!$C$27) -> 0.9 | ... AL26: =(1-$B$6)^((AL$8-1)/12)*(1-Inputs!$C$27) -> 0.9
A27: Cloud: compute | B27: $ | C27: =C13/1000*Inputs!$C$24*C26 -> 4320 | D27: =D13/1000*Inputs!$C$24*D26 -> 4428.432 | E27: =E13/1000*Inputs!$C$24*E26 -> 4539.5856 | F27: =F13/1000*Inputs!$C$24*F26 -> 4653.5292 | G27: =G13/1000*Inputs!$C$24*G26 -> 4770.3328 | H27: =H13/1000*Inputs!$C$24*H26 -> 4890.0682 | I27: =I13/1000*Inputs!$C$24*I26 -> 5012.8089 | J27: =J13/1000*Inputs!$C$24*J26 -> 5138.6304 | ... AL27: =AL13/1000*Inputs!$C$24*AL26 -> 10287.312
A28: Cloud: storage | B28: $ | C28: =C13/1000*Inputs!$C$25*C26 -> 1080 | D28: =D13/1000*Inputs!$C$25*D26 -> 1107.108 | E28: =E13/1000*Inputs!$C$25*E26 -> 1134.8964 | F28: =F13/1000*Inputs!$C$25*F26 -> 1163.3823 | G28: =G13/1000*Inputs!$C$25*G26 -> 1192.5832 | H28: =H13/1000*Inputs!$C$25*H26 -> 1222.517 | I28: =I13/1000*Inputs!$C$25*I26 -> 1253.2022 | J28: =J13/1000*Inputs!$C$25*J26 -> 1284.6576 | ... AL28: =AL13/1000*Inputs!$C$25*AL26 -> 2571.828
A29: Cloud: network | B29: $ | C29: =C13/1000*Inputs!$C$26*C26 -> 1800 | D29: =D13/1000*Inputs!$C$26*D26 -> 1845.18 | E29: =E13/1000*Inputs!$C$26*E26 -> 1891.494 | F29: =F13/1000*Inputs!$C$26*F26 -> 1938.9705 | G29: =G13/1000*Inputs!$C$26*G26 -> 1987.6387 | H29: =H13/1000*Inputs!$C$26*H26 -> 2037.5284 | I29: =I13/1000*Inputs!$C$26*I26 -> 2088.6704 | J29: =J13/1000*Inputs!$C$26*J26 -> 2141.096 | ... AL29: =AL13/1000*Inputs!$C$26*AL26 -> 4286.3801
A30: Cloud cost (total) | B30: $ | C30: =SUM(C27:C29) -> 7200 | D30: =SUM(D27:D29) -> 7380.72 | E30: =SUM(E27:E29) -> 7565.9761 | F30: =SUM(F27:F29) -> 7755.8821 | G30: =SUM(G27:G29) -> 7950.5547 | H30: =SUM(H27:H29) -> 8150.1136 | I30: =SUM(I27:I29) -> 8354.6815 | J30: =SUM(J27:J29) -> 8564.384 | ... AL30: =SUM(AL27:AL29) -> 17145.52
A31: Other cost of revenue | B31: $ | C31: =C22*Inputs!$C$29 -> 1472 | D31: =D22*Inputs!$C$29 -> 1508.9472 | E31: =E22*Inputs!$C$29 -> 1546.8218 | F31: =F22*Inputs!$C$29 -> 1585.647 | G31: =G22*Inputs!$C$29 -> 1625.4467 | H31: =H22*Inputs!$C$29 -> 1666.2455 | I31: =I22*Inputs!$C$29 -> 1708.0682 | J31: =J22*Inputs!$C$29 -> 1750.9407 | ... AL31: =AL22*Inputs!$C$29 -> 3505.3064
A32: Total cost of revenue | B32: $ | C32: =C25+C30+C31 -> 17792 | D32: =D25+D30+D31 -> 18156.855 | E32: =E25+E30+E31 -> 18529.548 | F32: =F25+F30+F31 -> 18910.256 | G32: =G25+G30+G31 -> 19299.158 | H32: =H25+H30+H31 -> 19696.437 | I32: =I25+I30+I31 -> 20102.282 | J32: =J25+J30+J31 -> 20516.885 | ... AL32: =AL25+AL30+AL31 -> 36622.619
A33: Margin and ROI position
A34: Gross margin | B34: $ | C34: =C22-C32 -> 11648 | D34: =D22-D32 -> 12022.089 | E34: =E22-E32 -> 12406.887 | F34: =F22-F32 -> 12802.684 | G34: =G22-G32 -> 13209.777 | H34: =H22-H32 -> 13628.472 | I34: =I22-I32 -> 14059.082 | J34: =J22-J32 -> 14501.929 | ... AL34: =AL22-AL32 -> 33483.508
A35: Gross margin % | B35: % | C35: =IF(C22=0,0,C34/C22) -> 0.39565217 | D35: =IF(D22=0,0,D34/D22) -> 0.39836017 | E35: =IF(E22=0,0,E34/E22) -> 0.4010445 | F35: =IF(F22=0,0,F34/F22) -> 0.40370536 | G35: =IF(G22=0,0,G34/G22) -> 0.40634296 | H35: =IF(H22=0,0,H34/H22) -> 0.40895751 | I35: =IF(I22=0,0,I34/I22) -> 0.4115492 | J35: =IF(J22=0,0,J34/J22) -> 0.41411823 | ... AL35: =IF(AL22=0,0,AL34/AL22) -> 0.47761172
A36: Cumulative gross margin | B36: $ | C36: =SUM($C34:C34) -> 11648 | D36: =SUM($C34:D34) -> 23670.089 | E36: =SUM($C34:E34) -> 36076.977 | F36: =SUM($C34:F34) -> 48879.661 | G36: =SUM($C34:G34) -> 62089.437 | H36: =SUM($C34:H34) -> 75717.909 | I36: =SUM($C34:I34) -> 89776.991 | J36: =SUM($C34:J34) -> 104278.92 | ... AL36: =SUM($C34:AL34) -> 751854.42
A37: Cumulative net position (after upfront investment) | B37: $ | C37: =C36-Inputs!$C$31 -> -738352 | D37: =D36-Inputs!$C$31 -> -726329.91 | E37: =E36-Inputs!$C$31 -> -713923.02 | F37: =F36-Inputs!$C$31 -> -701120.34 | G37: =G36-Inputs!$C$31 -> -687910.56 | H37: =H36-Inputs!$C$31 -> -674282.09 | I37: =I36-Inputs!$C$31 -> -660223.01 | J37: =J36-Inputs!$C$31 -> -645721.08 | ... AL37: =AL36-Inputs!$C$31 -> 1854.419
A38: Break-even reached (1 = yes) | B38: flag | C38: =IF(C37>=0,1,0) -> 0 | D38: =IF(D37>=0,1,0) -> 0 | E38: =IF(E37>=0,1,0) -> 0 | F38: =IF(F37>=0,1,0) -> 0 | G38: =IF(G37>=0,1,0) -> 0 | H38: =IF(H37>=0,1,0) -> 0 | I38: =IF(I37>=0,1,0) -> 0 | J38: =IF(J37>=0,1,0) -> 0 | ... AL38: =IF(AL37>=0,1,0) -> 1
A39: Unit economics
A40: Revenue per 1,000 interactions | B40: $ | C40: =IF(C13=0,0,C22/(C13/1000)) -> 73.6 | D40: =IF(D13=0,0,D22/(D13/1000)) -> 73.6 | E40: =IF(E13=0,0,E22/(E13/1000)) -> 73.6 | F40: =IF(F13=0,0,F22/(F13/1000)) -> 73.6 | G40: =IF(G13=0,0,G22/(G13/1000)) -> 73.6 | H40: =IF(H13=0,0,H22/(H13/1000)) -> 73.6 | I40: =IF(I13=0,0,I22/(I13/1000)) -> 73.6 | J40: =IF(J13=0,0,J22/(J13/1000)) -> 73.6 | ... AL40: =IF(AL13=0,0,AL22/(AL13/1000)) -> 73.6
...

Sheet Model_Base
A1: Monthly model: Base scenario
A2: Scenario levers (linked from Inputs) | B2: Value
A3: Monthly customer growth | B3: =Inputs!D5 -> 0.04
A4: Monthly growth in interactions per customer | B4: =Inputs!D6 -> 0.01
A5: Annual LLM token cost decline | B5: =Inputs!D7 -> 0.25
A6: Annual cloud unit cost decline | B6: =Inputs!D8 -> 0.05
A7: Efficiency gain on LLM cost | B7: =Inputs!D9 -> 0.1
A8: Line item | B8: Unit | C8: 1 | D8: 2 | E8: 3 | F8: 4 | G8: 5 | H8: 6 | I8: 7 | J8: 8 | K8: 9 | L8: 10 | M8: 11 | N8: 12 | O8: 13 | P8: 14 | Q8: 15 | R8: 16 | S8: 17 | T8: 18 | U8: 19 | V8: 20 | W8: 21 | X8: 22 | Y8: 23 | Z8: 24 | AA8: 25 | AB8: 26 | AC8: 27 | AD8: 28 | AE8: 29 | AF8: 30 | AG8: 31 | AH8: 32 | AI8: 33 | AJ8: 34 | AK8: 35 | AL8: 36
A9: Year | C9: =ROUNDUP(C8/12,0) -> 1 | D9: =ROUNDUP(D8/12,0) -> 1 | E9: =ROUNDUP(E8/12,0) -> 1 | F9: =ROUNDUP(F8/12,0) -> 1 | G9: =ROUNDUP(G8/12,0) -> 1 | H9: =ROUNDUP(H8/12,0) -> 1 | I9: =ROUNDUP(I8/12,0) -> 1 | J9: =ROUNDUP(J8/12,0) -> 1 | ... AL9: =ROUNDUP(AL8/12,0) -> 3
A10: Usage
A11: Active customers | B11: count | C11: =Inputs!$C$13*(1+$B$3)^(C$8-1) -> 200 | D11: =Inputs!$C$13*(1+$B$3)^(D$8-1) -> 208 | E11: =Inputs!$C$13*(1+$B$3)^(E$8-1) -> 216.32 | F11: =Inputs!$C$13*(1+$B$3)^(F$8-1) -> 224.9728 | G11: =Inputs!$C$13*(1+$B$3)^(G$8-1) -> 233.97171 | H11: =Inputs!$C$13*(1+$B$3)^(H$8-1) -> 243.33058 | I11: =Inputs!$C$13*(1+$B$3)^(I$8-1) -> 253.0638 | J11: =Inputs!$C$13*(1+$B$3)^(J$8-1) -> 263.18636 | ... AL11: =Inputs!$C$13*(1+$B$3)^(AL$8-1) -> 789.2178
A12: Interactions per customer | B12: count | C12: =Inputs!$C$14*(1+$B$4)^(C$8-1) -> 2000 | D12: =Inputs!$C$14*(1+$B$4)^(D$8-1) -> 2020 | E12: =Inputs!$C$14*(1+$B$4)^(E$8-1) -> 2040.2 | F12: =Inputs!$C$14*(1+$B$4)^(F$8-1) -> 2060.602 | G12: =Inputs!$C$14*(1+$B$4)^(G$8-1) -> 2081.208 | H12: =Inputs!$C$14*(1+$B$4)^(H$8-1) -> 2102.0201 | I12: =Inputs!$C$14*(1+$B$4)^(I$8-1) -> 2123.0403 | J12: =Inputs!$C$14*(1+$B$4)^(J$8-1) -> 2144.2707 | ... AL12: =Inputs!$C$14*(1+$B$4)^(AL$8-1) -> 2833.2055
A13: Total interactions | B13: count | C13: =C11*C12 -> 400000 | D13: =D11*D12 -> 420160 | E13: =E11*E12 -> 441336.06 | F13: =F11*F12 -> 463579.4 | G13: =G11*G12 -> 486943.8 | H13: =H11*H12 -> 511485.77 | I13: =I11*I12 -> 537264.65 | J13: =J11*J12 -> 564342.79 | ... AL13: =AL11*AL12 -> 2236016.2
A14: Tokens per interaction | B14: tokens | C14: =Inputs!$C$15 -> 4000 | D14: =Inputs!$C$15 -> 4000 | E14: =Inputs!$C$15 -> 4000 | F14: =Inputs!$C$15 -> 4000 | G14: =Inputs!$C$15 -> 4000 | H14: =Inputs!$C$15 -> 4000 | I14: =Inputs!$C$15 -> 4000 | J14: =Inputs!$C$15 -> 4000 | ... AL14: =Inputs!$C$15 -> 4000
A15: Total tokens (000s) | B15: 000s | C15: =C13*C14/1000 -> 1600000 | D15: =D13*D14/1000 -> 1680640 | E15: =E13*E14/1000 -> 1765344.3 | F15: =F13*F14/1000 -> 1854317.6 | G15: =G13*G14/1000 -> 1947775.2 | H15: =H13*H14/1000 -> 2045943.1 | I15: =I13*I14/1000 -> 2149058.6 | J15: =J13*J14/1000 -> 2257371.2 | ... AL15: =AL13*AL14/1000 -> 8944064.9
A16: Revenue
A17: On-demand tokens (000s) | B17: 000s | C17: =C15*(1-Inputs!$C$18) -> 960000 | D17: =D15*(1-Inputs!$C$18) -> 1008384 | E17: =E15*(1-Inputs!$C$18) -> 1059206.6 | F17: =F15*(1-Inputs!$C$18) -> 1112590.6 | G17: =G15*(1-Inputs!$C$18) -> 1168665.1 | H17: =H15*(1-Inputs!$C$18) -> 1227565.9 | I17: =I15*(1-Inputs!$C$18) -> 1289435.2 | J17: =J15*(1-Inputs!$C$18) -> 1354422.7 | ... AL17: =AL15*(1-Inputs!$C$18) -> 5366438.9
A18: Prepaid tokens (000s) | B18: 000s | C18: =C15*Inputs!$C$18 -> 640000 | D18: =D15*Inputs!$C$18 -> 672256 | E18: =E15*Inputs!$C$18 -> 706137.7 | F18: =F15*Inputs!$C$18 -> 741727.04 | G18: =G15*Inputs!$C$18 -> 779110.09 | H18: =H15*Inputs!$C$18 -> 818377.23 | I18: =I15*Inputs!$C$18 -> 859623.45 | J18: =J15*Inputs!$C$18 -> 902948.47 | ... AL18: =AL15*Inputs!$C$18 -> 3577625.9
A19: On-demand revenue | B19: $ | C19: =C17*Inputs!$C$17 -> 19200 | D19: =D17*Inputs!$C$17 -> 20167.68 | E19: =E17*Inputs!$C$17 -> 21184.131 | F19: =F17*Inputs!$C$17 -> 22251.811 | G19: =G17*Inputs!$C$17 -> 23373.303 | H19: =H17*Inputs!$C$17 -> 24551.317 | I19: =I17*Inputs!$C$17 -> 25788.703 | J19: =J17*Inputs!$C$17 -> 27088.454 | ... AL19: =AL17*Inputs!$C$17 -> 107328.78
A20: Prepaid revenue (discounted rate) | B20: $ | C20: =C18*Inputs!$C$17*(1-Inputs!$C$19) -> 10240 | D20: =D18*Inputs!$C$17*(1-Inputs!$C$19) -> 10756.096 | E20: =E18*Inputs!$C$17*(1-Inputs!$C$19) -> 11298.203 | F20: =F18*Inputs!$C$17*(1-Inputs!$C$19) -> 11867.633 | G20: =G18*Inputs!$C$17*(1-Inputs!$C$19) -> 12465.761 | H20: =H18*Inputs!$C$17*(1-Inputs!$C$19) -> 13094.036 | I20: =I18*Inputs!$C$17*(1-Inputs!$C$19) -> 13753.975 | J20: =J18*Inputs!$C$17*(1-Inputs!$C$19) -> 14447.175 | ... AL20: =AL18*Inputs!$C$17*(1-Inputs!$C$19) -> 57242.015
A21: Subscription revenue | B21: $ | C21: =C11*Inputs!$C$20 -> 0 | D21: =D11*Inputs!$C$20 -> 0 | E21: =E11*Inputs!$C$20 -> 0 | F21: =F11*Inputs!$C$20 -> 0 | G21: =G11*Inputs!$C$20 -> 0 | H21: =H11*Inputs!$C$20 -> 0 | I21: =I11*Inputs!$C$20 -> 0 | J21: =J11*Inputs!$C$20 -> 0 | ... AL21: =AL11*Inputs!$C$20 -> 0
A22: Total revenue | B22: $ | C22: =SUM(C19:C21) -> 29440 | D22: =SUM(D19:D21) -> 30923.776 | E22: =SUM(E19:E21) -> 32482.334 | F22: =SUM(F19:F21) -> 34119.444 | G22: =SUM(G19:G21) -> 35839.064 | H22: =SUM(H19:H21) -> 37645.353 | I22: =SUM(I19:I21) -> 39542.679 | J22: =SUM(J19:J21) -> 41535.63 | ... AL22: =SUM(AL19:AL21) -> 164570.79
A23: Cost of revenue
A24: LLM cost per 1,000 tokens (after decline) | B24: $ | C24: =Inputs!$C$22*(1-$B$5)^((C$8-1)/12) -> 0.006 | D24: =Inputs!$C$22*(1-$B$5)^((D$8-1)/12) -> 0.0058578695 | E24: =Inputs!$C$22*(1-$B$5)^((E$8-1)/12) -> 0.0057191058 | F24: =Inputs!$C$22*(1-$B$5)^((F$8-1)/12) -> 0.0055836292 | G24: =Inputs!$C$22*(1-$B$5)^((G$8-1)/12) -> 0.0054513618 | H24: =Inputs!$C$22*(1-$B$5)^((H$8-1)/12) -> 0.0053222276 | I24: =Inputs!$C$22*(1-$B$5)^((I$8-1)/12) -> 0.0051961524 | J24: =Inputs!$C$22*(1-$B$5)^((J$8-1)/12) -> 0.0050730638 | ... AL24: =Inputs!$C$22*(1-$B$5)^((AL$8-1)/12) -> 0.0025926662
A25: LLM cost (after efficiency gain) | B25: $ | C25: =C15*C24*(1-$B$7) -> 8640 | D25: =D15*D24*(1-$B$7) -> 8860.4727 | E25: =E15*E24*(1-$B$7) -> 9086.5714 | F25: =F15*F24*(1-$B$7) -> 9318.4397 | G25: =G15*G24*(1-$B$7) -> 9556.2246 | H25: =H15*H24*(1-$B$7) -> 9800.0773 | I25: =I15*I24*(1-$B$7) -> 10050.153 | J25: =J15*J24*(1-$B$7) -> 10306.609 | ... AL25: =AL15*AL24*(1-$B$7) -> 20870.077
A26: Cloud cost factor (price decline x (1 - discount)) | B26: factor | C26: =(1-$B$6)^((C$8-1)/12)*(1-Inputs!$C$27) -> 0.9 | D26: =(1-$B$6)^((D$8-1)/12)*(1-Inputs!$C$27) -> 0.89616121 | E26: =(1-$B$6)^((E$8-1)/12)*(1-Inputs!$C$27) -> 0.8923388 | F26: =(1-$B$6)^((F$8-1)/12)*(1-Inputs!$C$27) -> 0.88853269 | G26: =(1-$B$6)^((G$8-1)/12)*(1-Inputs!$C$27) -> 0.88474282 | H26: =(1-$B$6)^((H$8-1)/12)*(1-Inputs!$C$27) -> 0.88096911 | I26: =(1-$B$6)^((I$8-1)/12)*(1-Inputs!$C$27) -> 0.87721149 | J26: =(1-$B$6)^((J$8-1)/12)*(1-Inputs!$C$27) -> 0.8734699 | ... AL26: =(1-$B$6)^((AL$8-1)/12)*(1-Inputs!$C$27) -> 0.77494288
A27: Cloud: compute | B27: $ | C27: =C13/1000*Inputs!$C$24*C26 -> 4320 | D27: =D13/1000*Inputs!$C$24*D26 -> 4518.3731 | E27: =E13/1000*Inputs!$C$24*E26 -> 4725.8555 | F27: =F13/1000*Inputs!$C$24*F26 -> 4942.8654 | G27: =G13/1000*Inputs!$C$24*G26 -> 5169.8404 | H27: =H13/1000*Inputs!$C$24*H26 -> 5407.2379 | I27: =I13/1000*Inputs!$C$24*I26 -> 5655.5367 | J27: =J13/1000*Inputs!$C$24*J26 -> 5915.2373 | ... AL27: =AL13/1000*Inputs!$C$24*AL26 -> 20793.418
A28: Cloud: storage | B28: $ | C28: =C13/1000*Inputs!$C$25*C26 -> 1080 | D28: =D13/1000*Inputs!$C$25*D26 -> 1129.5933 | E28: =E13/1000*Inputs!$C$25*E26 -> 1181.4639 | F28: =F13/1000*Inputs!$C$25*F26 -> 1235.7164 | G28: =G13/1000*Inputs!$C$25*G26 -> 1292.4601 | H28: =H13/1000*Inputs!$C$25*H26 -> 1351.8095 | I28: =I13/1000*Inputs!$C$25*I26 -> 1413.8842 | J28: =J13/1000*Inputs!$C$25*J26 -> 1478.8093 | ... AL28: =AL13/1000*Inputs!$C$25*AL26 -> 5198.3545
A29: Cloud: network | B29: $ | C29: =C13/1000*Inputs!$C$26*C26 -> 1800 | D29: =D13/1000*Inputs!$C$26*D26 -> 1882.6555 | E29: =E13/1000*Inputs!$C$26*E26 -> 1969.1065 | F29: =F13/1000*Inputs!$C$26*F26 -> 2059.5273 | G29: =G13/1000*Inputs!$C$26*G26 -> 2154.1002 | H29: =H13/1000*Inputs!$C$26*H26 -> 2253.0158 | I29: =I13/1000*Inputs!$C$26*I26 -> 2356.4736 | J29: =J13/1000*Inputs!$C$26*J26 -> 2464.6822 | ... AL29: =AL13/1000*Inputs!$C$26*AL26 -> 8663.9242
A30: Cloud cost (total) | B30: $ | C30: =SUM(C27:C29) -> 7200 | D30: =SUM(D27:D29) -> 7530.6219 | E30: =SUM(E27:E29) -> 7876.4259 | F30: =SUM(F27:F29) -> 8238.1091 | G30: =SUM(G27:G29) -> 8616.4006 | H30: =SUM(H27:H29) -> 9012.0632 | I30: =SUM(I27:I29) -> 9425.8946 | J30: =SUM(J27:J29) -> 9858.7289 | ... AL30: =SUM(AL27:AL29) -> 34655.697
A31: Other cost of revenue | B31: $ | C31: =C22*Inputs!$C$29 -> 1472 | D31: =D22*Inputs!$C$29 -> 1546.1888 | E31: =E22*Inputs!$C$29 -> 1624.1167 | F31: =F22*Inputs!$C$29 -> 1705.9722 | G31: =G22*Inputs!$C$29 -> 1791.9532 | H31: =H22*Inputs!$C$29 -> 1882.2676 | I31: =I22*Inputs!$C$29 -> 1977.1339 | J31: =J22*Inputs!$C$29 -> 2076.7815 | ... AL31: =AL22*Inputs!$C$29 -> 8228.5397
A32: Total cost of revenue | B32: $ | C32: =C25+C30+C31 -> 17312 | D32: =D25+D30+D31 -> 17937.283 | E32: =E25+E30+E31 -> 18587.114 | F32: =F25+F30+F31 -> 19262.521 | G32: =G25+G30+G31 -> 19964.578 | H32: =H25+H30+H31 -> 20694.408 | I32: =I25+I30+I31 -> 21453.181 | J32: =J25+J30+J31 -> 22242.119 | ... AL32: =AL25+AL30+AL31 -> 63754.314
A33: Margin and ROI position
A34: Gross margin | B34: $ | C34: =C22-C32 -> 12128 | D34: =D22-D32 -> 12986.493 | E34: =E22-E32 -> 13895.22 | F34: =F22-F32 -> 14856.923 | G34: =G22-G32 -> 15874.485 | H34: =H22-H32 -> 16950.945 | I34: =I22-I32 -> 18089.498 | J34: =J22-J32 -> 19293.51 | ... AL34: =AL22-AL32 -> 100816.48
A35: Gross margin % | B35: % | C35: =IF(C22=0,0,C34/C22) -> 0.41195652 | D35: =IF(D22=0,0,D34/D22) -> 0.41995171 | E35: =IF(E22=0,0,E34/E22) -> 0.42777776 | F35: =IF(F22=0,0,F34/F22) -> 0.4354386 | G35: =IF(G22=0,0,G34/G22) -> 0.44293806 | H35: =IF(H22=0,0,H34/H22) -> 0.45027987 | I35: =IF(I22=0,0,I34/I22) -> 0.45746768 | J35: =IF(J22=0,0,J34/J22) -> 0.46450506 | ... AL35: =IF(AL22=0,0,AL34/AL22) -> 0.6126025
A36: Cumulative gross margin | B36: $ | C36: =SUM($C34:C34) -> 12128 | D36: =SUM($C34:D34) -> 25114.493 | E36: =SUM($C34:E34) -> 39009.713 | F36: =SUM($C34:F34) -> 53866.636 | G36: =SUM($C34:G34) -> 69741.121 | H36: =SUM($C34:H34) -> 86692.066 | I36: =SUM($C34:I34) -> 104781.56 | J36: =SUM($C34:J34) -> 124075.07 | ... AL36: =SUM($C34:AL34) -> 1570739.5
A37: Cumulative net position (after upfront investment) | B37: $ | C37: =C36-Inputs!$C$31 -> -737872 | D37: =D36-Inputs!$C$31 -> -724885.51 | E37: =E36-Inputs!$C$31 -> -710990.29 | F37: =F36-Inputs!$C$31 -> -696133.36 | G37: =G36-Inputs!$C$31 -> -680258.88 | H37: =H36-Inputs!$C$31 -> -663307.93 | I37: =I36-Inputs!$C$31 -> -645218.44 | J37: =J36-Inputs!$C$31 -> -625924.93 | ... AL37: =AL36-Inputs!$C$31 -> 820739.52
A38: Break-even reached (1 = yes) | B38: flag | C38: =IF(C37>=0,1,0) -> 0 | D38: =IF(D37>=0,1,0) -> 0 | E38: =IF(E37>=0,1,0) -> 0 | F38: =IF(F37>=0,1,0) -> 0 | G38: =IF(G37>=0,1,0) -> 0 | H38: =IF(H37>=0,1,0) -> 0 | I38: =IF(I37>=0,1,0) -> 0 | J38: =IF(J37>=0,1,0) -> 0 | ... AL38: =IF(AL37>=0,1,0) -> 1
A39: Unit economics
A40: Revenue per 1,000 interactions | B40: $ | C40: =IF(C13=0,0,C22/(C13/1000)) -> 73.6 | D40: =IF(D13=0,0,D22/(D13/1000)) -> 73.6 | E40: =IF(E13=0,0,E22/(E13/1000)) -> 73.6 | F40: =IF(F13=0,0,F22/(F13/1000)) -> 73.6 | G40: =IF(G13=0,0,G22/(G13/1000)) -> 73.6 | H40: =IF(H13=0,0,H22/(H13/1000)) -> 73.6 | I40: =IF(I13=0,0,I22/(I13/1000)) -> 73.6 | J40: =IF(J13=0,0,J22/(J13/1000)) -> 73.6 | ... AL40: =IF(AL13=0,0,AL22/(AL13/1000)) -> 73.6
...

Sheet Model_High
A1: Monthly model: High scenario
A2: Scenario levers (linked from Inputs) | B2: Value
A3: Monthly customer growth | B3: =Inputs!E5 -> 0.06
A4: Monthly growth in interactions per customer | B4: =Inputs!E6 -> 0.015
A5: Annual LLM token cost decline | B5: =Inputs!E7 -> 0.4
A6: Annual cloud unit cost decline | B6: =Inputs!E8 -> 0.1
A7: Efficiency gain on LLM cost | B7: =Inputs!E9 -> 0.2
A8: Line item | B8: Unit | C8: 1 | D8: 2 | E8: 3 | F8: 4 | G8: 5 | H8: 6 | I8: 7 | J8: 8 | K8: 9 | L8: 10 | M8: 11 | N8: 12 | O8: 13 | P8: 14 | Q8: 15 | R8: 16 | S8: 17 | T8: 18 | U8: 19 | V8: 20 | W8: 21 | X8: 22 | Y8: 23 | Z8: 24 | AA8: 25 | AB8: 26 | AC8: 27 | AD8: 28 | AE8: 29 | AF8: 30 | AG8: 31 | AH8: 32 | AI8: 33 | AJ8: 34 | AK8: 35 | AL8: 36
A9: Year | C9: =ROUNDUP(C8/12,0) -> 1 | D9: =ROUNDUP(D8/12,0) -> 1 | E9: =ROUNDUP(E8/12,0) -> 1 | F9: =ROUNDUP(F8/12,0) -> 1 | G9: =ROUNDUP(G8/12,0) -> 1 | H9: =ROUNDUP(H8/12,0) -> 1 | I9: =ROUNDUP(I8/12,0) -> 1 | J9: =ROUNDUP(J8/12,0) -> 1 | ... AL9: =ROUNDUP(AL8/12,0) -> 3
A10: Usage
A11: Active customers | B11: count | C11: =Inputs!$C$13*(1+$B$3)^(C$8-1) -> 200 | D11: =Inputs!$C$13*(1+$B$3)^(D$8-1) -> 212 | E11: =Inputs!$C$13*(1+$B$3)^(E$8-1) -> 224.72 | F11: =Inputs!$C$13*(1+$B$3)^(F$8-1) -> 238.2032 | G11: =Inputs!$C$13*(1+$B$3)^(G$8-1) -> 252.49539 | H11: =Inputs!$C$13*(1+$B$3)^(H$8-1) -> 267.64512 | I11: =Inputs!$C$13*(1+$B$3)^(I$8-1) -> 283.70382 | J11: =Inputs!$C$13*(1+$B$3)^(J$8-1) -> 300.72605 | ... AL11: =Inputs!$C$13*(1+$B$3)^(AL$8-1) -> 1537.2174
A12: Interactions per customer | B12: count | C12: =Inputs!$C$14*(1+$B$4)^(C$8-1) -> 2000 | D12: =Inputs!$C$14*(1+$B$4)^(D$8-1) -> 2030 | E12: =Inputs!$C$14*(1+$B$4)^(E$8-1) -> 2060.45 | F12: =Inputs!$C$14*(1+$B$4)^(F$8-1) -> 2091.3567 | G12: =Inputs!$C$14*(1+$B$4)^(G$8-1) -> 2122.7271 | H12: =Inputs!$C$14*(1+$B$4)^(H$8-1) -> 2154.568 | I12: =Inputs!$C$14*(1+$B$4)^(I$8-1) -> 2186.8865 | J12: =Inputs!$C$14*(1+$B$4)^(J$8-1) -> 2219.6898 | ... AL12: =Inputs!$C$14*(1+$B$4)^(AL$8-1) -> 3367.7626
A13: Total interactions | B13: count | C13: =C11*C12 -> 400000 | D13: =D11*D12 -> 430360 | E13: =E11*E12 -> 463024.32 | F13: =F11*F12 -> 498167.87 | G13: =G11*G12 -> 535978.81 | H13: =H11*H12 -> 576659.6 | I13: =I11*I12 -> 620428.07 | J13: =J11*J12 -> 667518.56 | ... AL13: =AL11*AL12 -> 5176983.2
A14: Tokens per interaction | B14: tokens | C14: =Inputs!$C$15 -> 4000 | D14: =Inputs!$C$15 -> 4000 | E14: =Inputs!$C$15 -> 4000 | F14: =Inputs!$C$15 -> 4000 | G14: =Inputs!$C$15 -> 4000 | H14: =Inputs!$C$15 -> 4000 | I14: =Inputs!$C$15 -> 4000 | J14: =Inputs!$C$15 -> 4000 | ... AL14: =Inputs!$C$15 -> 4000
A15: Total tokens (000s) | B15: 000s | C15: =C13*C14/1000 -> 1600000 | D15: =D13*D14/1000 -> 1721440 | E15: =E13*E14/1000 -> 1852097.3 | F15: =F13*F14/1000 -> 1992671.5 | G15: =G13*G14/1000 -> 2143915.2 | H15: =H13*H14/1000 -> 2306638.4 | I15: =I13*I14/1000 -> 2481712.3 | J15: =J13*J14/1000 -> 2670074.2 | ... AL15: =AL13*AL14/1000 -> 20707933
A16: Revenue
A17: On-demand tokens (000s) | B17: 000s | C17: =C15*(1-Inputs!$C$18) -> 960000 | D17: =D15*(1-Inputs!$C$18) -> 1032864 | E17: =E15*(1-Inputs!$C$18) -> 1111258.4 | F17: =F15*(1-Inputs!$C$18) -> 1195602.9 | G17: =G15*(1-Inputs!$C$18) -> 1286349.1 | H17: =H15*(1-Inputs!$C$18) -> 1383983 | I17: =I15*(1-Inputs!$C$18) -> 1489027.4 | J17: =J15*(1-Inputs!$C$18) -> 1602044.5 | ... AL17: =AL15*(1-Inputs!$C$18) -> 12424760
A18: Prepaid tokens (000s) | B18: 000s | C18: =C15*Inputs!$C$18 -> 640000 | D18: =D15*Inputs!$C$18 -> 688576 | E18: =E15*Inputs!$C$18 -> 740838.92 | F18: =F15*Inputs!$C$18 -> 797068.59 | G18: =G15*Inputs!$C$18 -> 857566.1 | H18: =H15*Inputs!$C$18 -> 922655.37 | I18: =I15*Inputs!$C$18 -> 992684.91 | J18: =J15*Inputs!$C$18 -> 1068029.7 | ... AL18: =AL15*Inputs!$C$18 -> 8283173.1
A19: On-demand revenue | B19: $ | C19: =C17*Inputs!$C$17 -> 19200 | D19: =D17*Inputs!$C$17 -> 20657.28 | E19: =E17*Inputs!$C$17 -> 22225.168 | F19: =F17*Inputs!$C$17 -> 23912.058 | G19: =G17*Inputs!$C$17 -> 25726.983 | H19: =H17*Inputs!$C$17 -> 27679.661 | I19: =I17*Inputs!$C$17 -> 29780.547 | J19: =J17*Inputs!$C$17 -> 32040.891 | ... AL19: =AL17*Inputs!$C$17 -> 248495.19
A20: Prepaid revenue (discounted rate) | B20: $ | C20: =C18*Inputs!$C$17*(1-Inputs!$C$19) -> 10240 | D20: =D18*Inputs!$C$17*(1-Inputs!$C$19) -> 11017.216 | E20: =E18*Inputs!$C$17*(1-Inputs!$C$19) -> 11853.423 | F20: =F18*Inputs!$C$17*(1-Inputs!$C$19) -> 12753.097 | G20: =G18*Inputs!$C$17*(1-Inputs!$C$19) -> 13721.058 | H20: =H18*Inputs!$C$17*(1-Inputs!$C$19) -> 14762.486 | I20: =I18*Inputs!$C$17*(1-Inputs!$C$19) -> 15882.959 | J20: =J18*Inputs!$C$17*(1-Inputs!$C$19) -> 17088.475 | ... AL20: =AL18*Inputs!$C$17*(1-Inputs!$C$19) -> 132530.77
A21: Subscription revenue | B21: $ | C21: =C11*Inputs!$C$20 -> 0 | D21: =D11*Inputs!$C$20 -> 0 | E21: =E11*Inputs!$C$20 -> 0 | F21: =F11*Inputs!$C$20 -> 0 | G21: =G11*Inputs!$C$20 -> 0 | H21: =H11*Inputs!$C$20 -> 0 | I21: =I11*Inputs!$C$20 -> 0 | J21: =J11*Inputs!$C$20 -> 0 | ... AL21: =AL11*Inputs!$C$20 -> 0
A22: Total revenue | B22: $ | C22: =SUM(C19:C21) -> 29440 | D22: =SUM(D19:D21) -> 31674.496 | E22: =SUM(E19:E21) -> 34078.59 | F22: =SUM(F19:F21) -> 36665.155 | G22: =SUM(G19:G21) -> 39448.041 | H22: =SUM(H19:H21) -> 42442.147 | I22: =SUM(I19:I21) -> 45663.506 | J22: =SUM(J19:J21) -> 49129.366 | ... AL22: =SUM(AL19:AL21) -> 381025.96
A23: Cost of revenue
A24: LLM cost per 1,000 tokens (after decline) | B24: $ | C24: =Inputs!$C$22*(1-$B$5)^((C$8-1)/12) -> 0.006 | D24: =Inputs!$C$22*(1-$B$5)^((D$8-1)/12) -> 0.0057499472 | E24: =Inputs!$C$22*(1-$B$5)^((E$8-1)/12) -> 0.0055103154 | F24: =Inputs!$C$22*(1-$B$5)^((F$8-1)/12) -> 0.0052806704 | G24: =Inputs!$C$22*(1-$B$5)^((G$8-1)/12) -> 0.005060596 | H24: =Inputs!$C$22*(1-$B$5)^((H$8-1)/12) -> 0.0048496933 | I24: =Inputs!$C$22*(1-$B$5)^((I$8-1)/12) -> 0.00464758 | J24: =Inputs!$C$22*(1-$B$5)^((J$8-1)/12) -> 0.0044538899 | ... AL24: =Inputs!$C$22*(1-$B$5)^((AL$8-1)/12) -> 0.0013523603
A25: LLM cost (after efficiency gain) | B25: $ | C25: =C15*C24*(1-$B$7) -> 7680 | D25: =D15*D24*(1-$B$7) -> 7918.5512 | E25: =E15*E24*(1-$B$7) -> 8164.5122 | F25: =F15*F24*(1-$B$7) -> 8418.1131 | G25: =G15*G24*(1-$B$7) -> 8679.5911 | H25: =H15*H24*(1-$B$7) -> 8949.191 | I25: =I15*I24*(1-$B$7) -> 9227.1651 | J25: =J15*J24*(1-$B$7) -> 9513.7734 | ... AL25: =AL15*AL24*(1-$B$7) -> 22403.668
A26: Cloud cost factor (price decline x (1 - discount)) | B26: factor | C26: =(1-$B$6)^((C$8-1)/12)*(1-Inputs!$C$27) -> 0.9 | D26: =(1-$B$6)^((D$8-1)/12)*(1-Inputs!$C$27) -> 0.89213255 | E26: =(1-$B$6)^((E$8-1)/12)*(1-Inputs!$C$27) -> 0.88433387 | F26: =(1-$B$6)^((F$8-1)/12)*(1-Inputs!$C$27) -> 0.87660337 | G26: =(1-$B$6)^((G$8-1)/12)*(1-Inputs!$C$27) -> 0.86894045 | H26: =(1-$B$6)^((H$8-1)/12)*(1-Inputs!$C$27) -> 0.86134451 | I26: =(1-$B$6)^((I$8-1)/12)*(1-Inputs!$C$27) -> 0.85381497 | J26: =(1-$B$6)^((J$8-1)/12)*(1-Inputs!$C$27) -> 0.84635125 | ... AL26: =(1-$B$6)^((AL$8-1)/12)*(1-Inputs!$C$27) -> 0.66188595
A27: Cloud: compute | B27: $ | C27: =C13/1000*Inputs!$C$24*C26 -> 4320 | D27: =D13/1000*Inputs!$C$24*D26 -> 4607.258 | E27: =E13/1000*Inputs!$C$24*E26 -> 4913.6171 | F27: =F13/1000*Inputs!$C$24*F26 -> 5240.3476 | G27: =G13/1000*Inputs!$C$24*G26 -> 5588.804 | H27: =H13/1000*Inputs!$C$24*H26 -> 5960.431 | I27: =I13/1000*Inputs!$C$24*I26 -> 6356.7692 | J27: =J13/1000*Inputs!$C$24*J26 -> 6779.462 | ... AL27: =AL13/1000*Inputs!$C$24*AL26 -> 41118.869
A28: Cloud: storage | B28: $ | C28: =C13/1000*Inputs!$C$25*C26 -> 1080 | D28: =D13/1000*Inputs!$C$25*D26 -> 1151.8145 | E28: =E13/1000*Inputs!$C$25*E26 -> 1228.4043 | F28: =F13/1000*Inputs!$C$25*F26 -> 1310.0869 | G28: =G13/1000*Inputs!$C$25*G26 -> 1397.201 | H28: =H13/1000*Inputs!$C$25*H26 -> 1490.1077 | I28: =I13/1000*Inputs!$C$25*I26 -> 1589.1923 | J28: =J13/1000*Inputs!$C$25*J26 -> 1694.8655 | ... AL28: =AL13/1000*Inputs!$C$25*AL26 -> 10279.717
A29: Cloud: network | B29: $ | C29: =C13/1000*Inputs!$C$26*C26 -> 1800 | D29: =D13/1000*Inputs!$C$26*D26 -> 1919.6908 | E29: =E13/1000*Inputs!$C$26*E26 -> 2047.3405 | F29: =F13/1000*Inputs!$C$26*F26 -> 2183.4782 | G29: =G13/1000*Inputs!$C$26*G26 -> 2328.6683 | H29: =H13/1000*Inputs!$C$26*H26 -> 2483.5129 | I29: =I13/1000*Inputs!$C$26*I26 -> 2648.6539 | J29: =J13/1000*Inputs!$C$26*J26 -> 2824.7758 | ... AL29: =AL13/1000*Inputs!$C$26*AL26 -> 17132.862
A30: Cloud cost (total) | B30: $ | C30: =SUM(C27:C29) -> 7200 | D30: =SUM(D27:D29) -> 7678.7633 | E30: =SUM(E27:E29) -> 8189.3619 | F30: =SUM(F27:F29) -> 8733.9127 | G30: =SUM(G27:G29) -> 9314.6734 | H30: =SUM(H27:H29) -> 9934.0516 | I30: =SUM(I27:I29) -> 10594.615 | J30: =SUM(J27:J29) -> 11299.103 | ... AL30: =SUM(AL27:AL29) -> 68531.449
A31: Other cost of revenue | B31: $ | C31: =C22*Inputs!$C$29 -> 1472 | D31: =D22*Inputs!$C$29 -> 1583.7248 | E31: =E22*Inputs!$C$29 -> 1703.9295 | F31: =F22*Inputs!$C$29 -> 1833.2578 | G31: =G22*Inputs!$C$29 -> 1972.402 | H31: =H22*Inputs!$C$29 -> 2122.1073 | I31: =I22*Inputs!$C$29 -> 2283.1753 | J31: =J22*Inputs!$C$29 -> 2456.4683 | ... AL31: =AL22*Inputs!$C$29 -> 19051.298
A32: Total cost of revenue | B32: $ | C32: =C25+C30+C31 -> 16352 | D32: =D25+D30+D31 -> 17181.039 | E32: =E25+E30+E31 -> 18057.804 | F32: =F25+F30+F31 -> 18985.284 | G32: =G25+G30+G31 -> 19966.667 | H32: =H25+H30+H31 -> 21005.35 | I32: =I25+I30+I31 -> 22104.956 | J32: =J25+J30+J31 -> 23269.345 | ... AL32: =AL25+AL30+AL31 -> 109986.41
A33: Margin and ROI position
A34: Gross margin | B34: $ | C34: =C22-C32 -> 13088 | D34: =D22-D32 -> 14493.457 | E34: =E22-E32 -> 16020.787 | F34: =F22-F32 -> 17679.872 | G34: =G22-G32 -> 19481.374 | H34: =H22-H32 -> 21436.797 | I34: =I22-I32 -> 23558.55 | J34: =J22-J32 -> 25860.021 | ... AL34: =AL22-AL32 -> 271039.55
A35: Gross margin % | B35: % | C35: =IF(C22=0,0,C34/C22) -> 0.44456522 | D35: =IF(D22=0,0,D34/D22) -> 0.45757497 | E35: =IF(E22=0,0,E34/E22) -> 0.47011295 | F35: =IF(F22=0,0,F34/F22) -> 0.4821982 | G35: =IF(G22=0,0,G34/G22) -> 0.49384897 | H35: =IF(H22=0,0,H34/H22) -> 0.50508276 | I35: =IF(I22=0,0,I34/I22) -> 0.51591637 | J35: =IF(J22=0,0,J34/J22) -> 0.52636586 | ... AL35: =IF(AL22=0,0,AL34/AL22) -> 0.71134142
A36: Cumulative gross margin | B36: $ | C36: =SUM($C34:C34) -> 13088 | D36: =SUM($C34:D34) -> 27581.457 | E36: =SUM($C34:E34) -> 43602.243 | F36: =SUM($C34:F34) -> 61282.115 | G36: =SUM($C34:G34) -> 80763.489 | H36: =SUM($C34:H34) -> 102200.29 | I36: =SUM($C34:I34) -> 125758.84 | J36: =SUM($C34:J34) -> 151618.86 | ... AL36: =SUM($C34:AL34) -> 3275287.4
A37: Cumulative net position (after upfront investment) | B37: $ | C37: =C36-Inputs!$C$31 -> -736912 | D37: =D36-Inputs!$C$31 -> -722418.54 | E37: =E36-Inputs!$C$31 -> -706397.76 | F37: =F36-Inputs!$C$31 -> -688717.88 | G37: =G36-Inputs!$C$31 -> -669236.51 | H37: =H36-Inputs!$C$31 -> -647799.71 | I37: =I36-Inputs!$C$31 -> -624241.16 | J37: =J36-Inputs!$C$31 -> -598381.14 | ... AL37: =AL36-Inputs!$C$31 -> 2525287.4
A38: Break-even reached (1 = yes) | B38: flag | C38: =IF(C37>=0,1,0) -> 0 | D38: =IF(D37>=0,1,0) -> 0 | E38: =IF(E37>=0,1,0) -> 0 | F38: =IF(F37>=0,1,0) -> 0 | G38: =IF(G37>=0,1,0) -> 0 | H38: =IF(H37>=0,1,0) -> 0 | I38: =IF(I37>=0,1,0) -> 0 | J38: =IF(J37>=0,1,0) -> 0 | ... AL38: =IF(AL37>=0,1,0) -> 1
A39: Unit economics
A40: Revenue per 1,000 interactions | B40: $ | C40: =IF(C13=0,0,C22/(C13/1000)) -> 73.6 | D40: =IF(D13=0,0,D22/(D13/1000)) -> 73.6 | E40: =IF(E13=0,0,E22/(E13/1000)) -> 73.6 | F40: =IF(F13=0,0,F22/(F13/1000)) -> 73.6 | G40: =IF(G13=0,0,G22/(G13/1000)) -> 73.6 | H40: =IF(H13=0,0,H22/(H13/1000)) -> 73.6 | I40: =IF(I13=0,0,I22/(I13/1000)) -> 73.6 | J40: =IF(J13=0,0,J22/(J13/1000)) -> 73.6 | ... AL40: =IF(AL13=0,0,AL22/(AL13/1000)) -> 73.6
...

Sheet Summary
A1: Summary: ROI corridor, annual results and unit economics
A2: Everything on this sheet is formula-driven from the Model tabs and the Inputs sheet.
A4: ROI corridor (pre-investment evaluation) | B4: Low | C4: Base | D4: High | E4: How to read it
A5: Upfront investment ($) | B5: =Inputs!$C$31 -> 750000 | C5: =Inputs!$C$31 -> 750000 | D5: =Inputs!$C$31 -> 750000 | E5: From Inputs.
A6: Cumulative gross margin, 36 months ($) | B6: =Model_Low!$AL$36 -> 751854.42 | C6: =Model_Base!$AL$36 -> 1570739.5 | D6: =Model_High!$AL$36 -> 3275287.4 | E6: Net gain before investment: the benefit used for ROI.
A7: ROI ceiling: standard ROI | B7: =IF(B5=0,"n/a",(B6-B5)/B5) -> 0.0024725587 | C7: =IF(C5=0,"n/a",(C6-C5)/C5) -> 1.0943194 | D7: =IF(D5=0,"n/a",(D6-D5)/D5) -> 3.3670499 | E7: (Cumulative gross margin - investment) / investment.
A8: Combined risk factor | B8: =Inputs!$C$35 -> 0.6885 | C8: =Inputs!$C$35 -> 0.6885 | D8: =Inputs!$C$35 -> 0.6885 | E8: From Inputs: (1 - technical) x (1 - data) x (1 - adoption).
A9: Risk-adjusted cumulative benefit ($) | B9: =B6*B8 -> 517651.77 | C9: =C6*C8 -> 1081454.2 | D9: =D6*D8 -> 2255035.4 | E9: Benefit after the risk haircut.
A10: ROI floor: risk-adjusted ROI | B10: =IF(B5=0,"n/a",(B9-B5)/B5) -> -0.30979764 | C10: =IF(C5=0,"n/a",(C9-C5)/C5) -> 0.44193888 | D10: =IF(D5=0,"n/a",(D9-D5)/D5) -> 2.0067139 | E10: (Risk-adjusted benefit - investment) / investment.
A11: Payback month | B11: =IFERROR(INDEX(Model_Low!$C$8:$AL$8,MATCH(1,Model_Low!$C$38:$AL$38,0)),"Beyond 36 months") -> 36 | C11: =IFERROR(INDEX(Model_Base!$C$8:$AL$8,MATCH(1,Model_Base!$C$38:$AL$38,0)),"Beyond 36 months") -> 26 | D11: =IFERROR(INDEX(Model_High!$C$8:$AL$8,MATCH(1,Model_High!$C$38:$AL$38,0)),"Beyond 36 months") -> 21 | E11: First month cumulative gross margin recovers the upfront investment.
A12: Adoption dip: lowest cumulative net position ($) | B12: =MIN(Model_Low!$C$37:$AL$37) -> -738352 | C12: =MIN(Model_Base!$C$37:$AL$37) -> -737872 | D12: =MIN(Model_High!$C$37:$AL$37) -> -736912 | E12: Depth of the dip while costs are front-loaded and returns are building.
A13: Adoption dip: month of lowest position | B13: =INDEX(Model_Low!$C$8:$AL$8,MATCH(B12,Model_Low!$C$37:$AL$37,0)) -> 1 | C13: =INDEX(Model_Base!$C$8:$AL$8,MATCH(C12,Model_Base!$C$37:$AL$37,0)) -> 1 | D13: =INDEX(Model_High!$C$8:$AL$8,MATCH(D12,Model_High!$C$37:$AL$37,0)) -> 1 | E13: Month at which the position stops getting worse.
A15: Corridor across scenarios | B15: ROI
A16: Floor: Low scenario, risk-adjusted ROI | B16: =B10 -> -0.30979764
A17: Base case floor (risk-adjusted) | B17: =C10 -> 0.44193888
A18: Base case ceiling (standard) | B18: =C7 -> 1.0943194
A19: Ceiling: High scenario, standard ROI | B19: =D7 -> 3.3670499
A21: Production stage: realized ROI vs plan (Base) | B21: Value | E21: How to read it
A22: Months of actuals | B22: =Inputs!$C$37 -> 12
A23: Realized ROI to date | B23: =IF(OR(Inputs!$C$38=0,Inputs!$C$37<1,Inputs!$C$37>36),"Enter actuals on Inputs",(Inputs!$C$39-Inputs!$C$38)/Inputs!$C$38) -> -0.74666667 | E23: (Actual cumulative gross margin - actual investment) / actual investment.
A24: Plan ROI at the same month (Base) | B24: =IF(OR(Inputs!$C$31=0,Inputs!$C$37<1,Inputs!$C$37>36),"n/a",(INDEX(Model_Base!$C$36:$AL$36,Inputs!$C$37)-Inputs!$C$31)/Inputs!$C$31) -> -0.7136981 | E24: Same formula applied to the Base plan, so the comparison is like for like.
A25: Gap: realized minus plan (percentage points) | B25: =IF(AND(ISNUMBER(B23),ISNUMBER(B24)),B23-B24,"n/a") -> -0.032968566 | E25: Positive = ahead of plan. Use it to narrow the gap between projection and delivered result.
A27: Annual summary
A28: Scenario and metric | B28: 1 | C28: 2 | D28: 3
A29: Low
A30: Revenue ($) | B30: =SUMIFS(Model_Low!$C$22:$AL$22,Model_Low!$C$9:$AL$9,B$28) -> 406370.73 | C30: =SUMIFS(Model_Low!$C$22:$AL$22,Model_Low!$C$9:$AL$9,C$28) -> 547163.63 | D30: =SUMIFS(Model_Low!$C$22:$AL$22,Model_Low!$C$9:$AL$9,D$28) -> 736736.22
A31: Total cost of revenue ($) | B31: =SUMIFS(Model_Low!$C$32:$AL$32,Model_Low!$C$9:$AL$9,B$28) -> 239399.13 | C31: =SUMIFS(Model_Low!$C$32:$AL$32,Model_Low!$C$9:$AL$9,C$28) -> 306225.65 | D31: =SUMIFS(Model_Low!$C$32:$AL$32,Model_Low!$C$9:$AL$9,D$28) -> 392791.37
A32: Gross margin ($) | B32: =SUMIFS(Model_Low!$C$34:$AL$34,Model_Low!$C$9:$AL$9,B$28) -> 166971.6 | C32: =SUMIFS(Model_Low!$C$34:$AL$34,Model_Low!$C$9:$AL$9,C$28) -> 240937.97 | D32: =SUMIFS(Model_Low!$C$34:$AL$34,Model_Low!$C$9:$AL$9,D$28) -> 343944.85
A33: Gross margin % | B33: =IF(B30=0,0,B32/B30) -> 0.41088491 | C33: =IF(C30=0,0,C32/C30) -> 0.44033989 | D33: =IF(D30=0,0,D32/D30) -> 0.46684938
A34: Base
A35: Revenue ($) | B35: =SUMIFS(Model_Base!$C$22:$AL$22,Model_Base!$C$9:$AL$9,B$28) -> 469686.68 | C35: =SUMIFS(Model_Base!$C$22:$AL$22,Model_Base!$C$9:$AL$9,C$28) -> 847353.84 | D35: =SUMIFS(Model_Base!$C$22:$AL$22,Model_Base!$C$9:$AL$9,D$28) -> 1528696.8
A36: Total cost of revenue ($) | B36: =SUMIFS(Model_Base!$C$32:$AL$32,Model_Base!$C$9:$AL$9,B$28) -> 254960.26 | C36: =SUMIFS(Model_Base!$C$32:$AL$32,Model_Base!$C$9:$AL$9,C$28) -> 395956.33 | D36: =SUMIFS(Model_Base!$C$32:$AL$32,Model_Base!$C$9:$AL$9,D$28) -> 624081.23
A37: Gross margin ($) | B37: =SUMIFS(Model_Base!$C$34:$AL$34,Model_Base!$C$9:$AL$9,B$28) -> 214726.42 | C37: =SUMIFS(Model_Base!$C$34:$AL$34,Model_Base!$C$9:$AL$9,C$28) -> 451397.51 | D37: =SUMIFS(Model_Base!$C$34:$AL$34,Model_Base!$C$9:$AL$9,D$28) -> 904615.58
A38: Gross margin % | B38: =IF(B35=0,0,B37/B35) -> 0.4571695 | C38: =IF(C35=0,0,C37/C35) -> 0.5327143 | D38: =IF(D35=0,0,D37/D35) -> 0.59175605
A39: High
A40: Revenue ($) | B40: =SUMIFS(Model_High!$C$22:$AL$22,Model_High!$C$9:$AL$9,B$28) -> 545287.24 | C40: =SUMIFS(Model_High!$C$22:$AL$22,Model_High!$C$9:$AL$9,C$28) -> 1311862.2 | D40: =SUMIFS(Model_High!$C$22:$AL$22,Model_High!$C$9:$AL$9,D$28) -> 3156102.6
A41: Total cost of revenue ($) | B41: =SUMIFS(Model_High!$C$32:$AL$32,Model_High!$C$9:$AL$9,B$28) -> 263089.34 | C41: =SUMIFS(Model_High!$C$32:$AL$32,Model_High!$C$9:$AL$9,C$28) -> 497067.5 | D41: =SUMIFS(Model_High!$C$32:$AL$32,Model_High!$C$9:$AL$9,D$28) -> 977807.81
A42: Gross margin ($) | B42: =SUMIFS(Model_High!$C$34:$AL$34,Model_High!$C$9:$AL$9,B$28) -> 282197.9 | C42: =SUMIFS(Model_High!$C$34:$AL$34,Model_High!$C$9:$AL$9,C$28) -> 814794.72 | D42: =SUMIFS(Model_High!$C$34:$AL$34,Model_High!$C$9:$AL$9,D$28) -> 2178294.8
A43: Gross margin % | B43: =IF(B40=0,0,B42/B40) -> 0.51752156 | C43: =IF(C40=0,0,C42/C40) -> 0.62109779 | D43: =IF(D40=0,0,D42/D40) -> 0.69018504
A45: Cost mix over 36 months (share of total cost of revenue) | B45: Low | C45: Base | D45: High | E45: How to read it
...
